<?xml version="1.0"?>
<robot name="bumperbot" xmlns:xacro="http://ros.org/wiki/xacro">

    <!-- Include Gazebo Parameters -->
    <xacro:include filename="$(find bot_description)/urdf/bot_gazebo.xacro" />

    <!-- Include ros2_control Plugins -->
    <xacro:include filename="$(find bot_description)/urdf/bot_ros2_control.xacro" />

    <xacro:include filename="inertial_macros.xacro"/>

    <material name="white">
        <color rgba="1 1 1 1"/>
    </material>
    
    <material name="orange">
        <color rgba="1 0.3 0.1 1"/>
    </material>
    
    <material name="blue">
        <color rgba="0.2 0.2 1 1"/>
    </material>
    
    <material name="black">
        <color rgba="0 0 0 1"/>
    </material>

    <material name="grey">
        <color rgba="0.5 0.5 0.5 1" />
    </material>

    <material name="red">
        <color rgba="1 0 0 1"/>
    </material>
    
    <!-- base_footprint (projection of base_link on the ground) -->

    <link name="base_footprint"/>



    <link name="base_link">
        <visual>
            <origin xyz="0.0 0.0 0.0" rpy="0 0 0" />
            <geometry>
                <box size="0.2 0.2 0.1" />
            </geometry>
            <material name="orange"/>
        </visual>
  
        <collision>
            <origin rpy="0 0 0" xyz="0 0 0"/>
            <geometry>
                <box size="0.2 0.2 0.1" />
            </geometry>
        </collision>

        <xacro:inertial_box mass="0.5" x="0.3" y="0.3" z="0.15">
            <origin xyz="0.0 0.0 0.0" rpy="0 0 0"/>
        </xacro:inertial_box>
        
    </link>

    <joint name="base_joint" type="fixed">
        <parent link="base_footprint"/>
        <child link="base_link"/>
        <origin xyz="0.1 0.0 0.05" rpy="0 0 0"/>
    </joint>

    <link name="wheel_left_link">
        <visual>
            <origin xyz="0 0 0" rpy="-1.5708 0 0" />
            <geometry>
                <cylinder length="0.03" radius="0.06" />
            </geometry>
            <material name="black"/>
        </visual>

  
        <collision>
            <origin xyz="0 0.015 0" rpy="1.57 0 0"/>
            <geometry>
                <cylinder length="0.03" radius="0.06" />
            </geometry>
        </collision>

        <xacro:inertial_cylinder mass="0.1" length="0.03" radius="0.06">
            <origin xyz="0 0 0" rpy="0 0 0"/>
        </xacro:inertial_cylinder>
    </link>
  
    <joint name="wheel_left_joint" type="continuous">
        <origin xyz="-0.035 0.115 -0.01" rpy="0 0 0" />
        <parent link="base_link" />
        <child link="wheel_left_link" />
        <axis xyz="0 1 0" />
    </joint>

    <link name="wheel_right_link">
        <visual>
            <origin xyz="0 0 0" rpy="-1.5708 0 0" />
            <geometry>
                <cylinder length="0.03" radius="0.06" />
            </geometry>
            <material name="black"/>
        </visual>

  
        <collision>
            <origin xyz="0 0.015 0" rpy="1.57 0 0"/>
            <geometry>
                <cylinder length="0.03" radius="0.06" />
            </geometry>
        </collision>

        <xacro:inertial_cylinder mass="0.1" length="0.03" radius="0.06">
            <origin xyz="0 0 0" rpy="0 0 0"/>
        </xacro:inertial_cylinder>
    </link>
  
    <joint name="wheel_right_joint" type="continuous">
        <origin xyz="-0.035 -0.115 -0.01" rpy="0 0 0" />
        <parent link="base_link" />
        <child link="wheel_right_link" />
        <axis xyz="0 1 0" />
    </joint>

    <link name="caster_link">
        <visual>
            <origin xyz="0 0 0" rpy="0 0 0" />
            <geometry>
                <sphere radius="0.021" />
            </geometry>
            <material name="white"/>
        </visual>
  
        <collision>
            <origin xyz="0 0 0" rpy="0 0 0"/>
            <geometry>
                <sphere radius="0.021" />
            </geometry>
        </collision>

        <xacro:inertial_sphere mass="0.1" radius="0.021">
            <origin xyz="0 0 0" rpy="0 0 0"/>
        </xacro:inertial_sphere>
    </link>
  
    <joint name="caster_joint" type="fixed">
        <origin xyz="0.061 0.0 -0.05" rpy="0 0 0" />
        <parent link="base_link" />
        <child link="caster_link" />
        <axis xyz="0 0 0" />
    </joint>

    <link name="lidar_link">
        <visual>
            <origin xyz="0 0 0" rpy="0 0 0" />
            <geometry>
                <cylinder radius="0.02" length="0.01"/>
            </geometry>
            <material name="red"/>
        </visual>
  
        <collision>
            <origin xyz="0 0 0" rpy="0 0 0"/>
            <geometry>
                <cylinder radius="0.03" length="0.04"/>
            </geometry>
        </collision>

        <xacro:inertial_cylinder mass="0.1" length="0.01" radius="0.03">
            <origin xyz="0 0 0" rpy="0 0 0"/>
        </xacro:inertial_cylinder>
    </link>
  
    <joint name="lidar_joint" type="fixed">
        <origin xyz="0.0 0.0 0.055" rpy="0 0 0" />
        <parent link="base_link" />
        <child link="lidar_link" />
        <axis xyz="0 0 0" />
    </joint>


    <link name="camera_link">
        <visual>
            <origin xyz="0 0 0" rpy="0 0 0" />
            <geometry>
                <box size="0.01 0.01 0.01" />
            </geometry>
            <material name="grey"/>
        </visual>
  
        <collision>
            <origin xyz="0 0 0" rpy="0 0 0"/>
            <geometry>
                <box size="0.01 0.01 0.01" />
            </geometry>
        </collision>

        
    </link>
  
    <joint name="camera_joint" type="fixed">
        <origin xyz="0.1 0.0 0.0" rpy="0 0 0" />
        <parent link="base_link" />
        <child link="camera_link" />
        <axis xyz="0 0 0" />
    </joint>


    

</robot>